<?xml version="1.0" encoding="utf-8" ?>
<!-- =================================================================================== -->
<!-- |    This document was autogenerated by xacro from tm1100_robot.urdf.xacro        | -->
<!-- |    EDITING THIS FILE BY HAND IS NOT RECOMMENDED                                 | -->
<!-- =================================================================================== -->
<robot name="tm1100">
    <gazebo>
        <plugin filename="libgazebo_ros_control.so" name="gazebo_ros_control">
            <!--robotNamespace>/</robotNamespace-->
            <!--robotSimType>gazebo_ros_control/DefaultRobotHWSim</robotSimType-->
            <legacyModeNS>true</legacyModeNS>
        </plugin>
        <!--
    <plugin name="gazebo_ros_power_monitor_controller" filename="libgazebo_ros_power_monitor.so">
      <alwaysOn>true</alwaysOn>
      <updateRate>1.0</updateRate>
      <timeout>5</timeout>
      <powerStateTopic>power_state</powerStateTopic>
      <powerStateRate>10.0</powerStateRate>
      <fullChargeCapacity>87.78</fullChargeCapacity>     
      <dischargeRate>-474</dischargeRate>
      <chargeRate>525</chargeRate>
      <dischargeVoltage>15.52</dischargeVoltage>
      <chargeVoltage>16.41</chargeVoltage>
    </plugin>
    -->
    </gazebo>
    <gazebo reference="base_link">
        <selfCollide>true</selfCollide>
    </gazebo>
    <gazebo reference="shoulder_1_link">
        <selfCollide>true</selfCollide>
    </gazebo>
    <gazebo reference="arm_1_link">
        <selfCollide>true</selfCollide>
    </gazebo>
    <gazebo reference="arm_2_link">
        <selfCollide>true</selfCollide>
    </gazebo>
    <gazebo reference="wrist_1_link">
        <selfCollide>true</selfCollide>
    </gazebo>
    <gazebo reference="wrist_2_link">
        <selfCollide>true</selfCollide>
    </gazebo>
    <gazebo reference="wrist_3_link">
        <selfCollide>true</selfCollide>
    </gazebo>
    <transmission name="shoulder_1_trans">
        <type>transmission_interface/SimpleTransmission</type>
        <joint name="shoulder_1_joint">
            <hardwareInterface>hardware_interface/PositionJointInterface</hardwareInterface>
        </joint>
        <actuator name="shoulder_1_motor">
            <mechanicalReduction>1</mechanicalReduction>
        </actuator>
    </transmission>
    <transmission name="shoulder_2_trans">
        <type>transmission_interface/SimpleTransmission</type>
        <joint name="shoulder_2_joint">
            <hardwareInterface>hardware_interface/PositionJointInterface</hardwareInterface>
        </joint>
        <actuator name="shoulder_2_motor">
            <mechanicalReduction>1</mechanicalReduction>
        </actuator>
    </transmission>
    <transmission name="elbow_1_trans">
        <type>transmission_interface/SimpleTransmission</type>
        <joint name="elbow_1_joint">
            <hardwareInterface>hardware_interface/PositionJointInterface</hardwareInterface>
        </joint>
        <actuator name="elbow_1_motor">
            <mechanicalReduction>1</mechanicalReduction>
        </actuator>
    </transmission>
    <transmission name="wrist_1_trans">
        <type>transmission_interface/SimpleTransmission</type>
        <joint name="wrist_1_joint">
            <hardwareInterface>hardware_interface/PositionJointInterface</hardwareInterface>
        </joint>
        <actuator name="wrist_1_motor">
            <mechanicalReduction>1</mechanicalReduction>
        </actuator>
    </transmission>
    <transmission name="wrist_2_trans">
        <type>transmission_interface/SimpleTransmission</type>
        <joint name="wrist_2_joint">
            <hardwareInterface>hardware_interface/PositionJointInterface</hardwareInterface>
        </joint>
        <actuator name="wrist_2_motor">
            <mechanicalReduction>1</mechanicalReduction>
        </actuator>
    </transmission>
    <transmission name="wrist_3_trans">
        <type>transmission_interface/SimpleTransmission</type>
        <joint name="wrist_3_joint">
            <hardwareInterface>hardware_interface/PositionJointInterface</hardwareInterface>
        </joint>
        <actuator name="wrist_3_motor">
            <mechanicalReduction>1</mechanicalReduction>
        </actuator>
    </transmission>
    <link name="base_link">
        <visual>
            <geometry>
                <mesh filename="package://tm_description/meshes/tm1100/visual/Base.STL" />
            </geometry>
            <material name="Grey">
                <color rgba="0.5 0.5 0.5 1.0" />
            </material>
        </visual>
        <collision>
            <geometry>
                <mesh filename="package://tm_description/meshes/tm1100/collision/base.STL" />
            </geometry>
        </collision>
        
<inertial>
            <mass value="1.0" />
            <origin rpy="0 0 0" xyz="0.0 0.0 0.0" />
            <inertia ixx="0.00110833289" ixy="0.0" ixz="0.0" iyy="0.00110833289" iyz="0.0" izz="0.0018" />
        </inertial>

    </link>
    <link name="shoulder_1_link">
        <visual>
            <geometry>
                <mesh filename="package://tm_description/meshes/tm1100/visual/Shoulder1.STL" />
            </geometry>
            <material name="DarkOlive">
                <color rgba="0.3 0.3 0.25 1.0" />
            </material>
        </visual>
        <collision>
            <geometry>
                <mesh filename="package://tm_description/meshes/tm1100/collision/shoulder_1.STL" />
            </geometry>
        </collision>
        
<inertial>
            <mass value="4.5" />
            <origin rpy="0 0 0" xyz="0.0 0.0 0.0" />
            <inertia ixx="0.012487495005" ixy="0.0" ixz="0.0" iyy="0.012487495005" iyz="0.0" izz="0.0081" />
        </inertial>

    </link>
    <joint name="shoulder_1_joint" type="revolute">
        <parent link="base_link" />
        <child link="shoulder_1_link" />
        <origin rpy="-1.570796325 0.0 0.0" xyz="0.0 0.0 0.1652" />
        <axis xyz="0 -1 0" />
        <limit effort="150.0" lower="-6.2831853" upper="6.2831853" velocity="3.15" />
        <dynamics damping="0.0" friction="0.0" />
    </joint>
    <link name="arm_1_link">
        <visual>
            <geometry>
                <mesh filename="package://tm_description/meshes/tm1100/visual/Arm1.STL" />
            </geometry>
            <material name="DarkOlive">
                <color rgba="0.3 0.3 0.25 1.0" />
            </material>
        </visual>
        <collision>
            <geometry>
                <mesh filename="package://tm_description/meshes/tm1100/collision/arm_1.STL" />
            </geometry>
        </collision>
        
<inertial>
            <mass value="10.5" />
            <origin rpy="0 0 0" xyz="0.0 0.0 0.28" />
            <inertia ixx="0.28384988646" ixy="0.0" ixz="0.0" iyy="0.28384988646" iyz="0.0" izz="0.0189" />
        </inertial>

    </link>
    <joint name="shoulder_2_joint" type="revolute">
        <parent link="shoulder_1_link" />
        <child link="arm_1_link" />
        <origin rpy="0.0 0.0 -1.570796325" xyz="0.0 0.0 -0.1801" />
        <axis xyz="0 0 1" />
        <limit effort="150.0" lower="-4.712388975" upper="4.712388975" velocity="3.15" />
        <dynamics damping="0.0" friction="0.0" />
    </joint>
    <link name="arm_2_link">
        <visual>
            <geometry>
                <mesh filename="package://tm_description/meshes/tm1100/visual/Arm2.STL" />
            </geometry>
            <material name="DarkOlive">
                <color rgba="0.3 0.3 0.25 1.0" />
            </material>
        </visual>
        <collision>
            <geometry>
                <mesh filename="package://tm_description/meshes/tm1100/collision/arm_2.STL" />
            </geometry>
        </collision>
        
<inertial>
            <mass value="2.1" />
            <origin rpy="0 0 0" xyz="0.0 0.0 0.25" />
            <inertia ixx="0.045639981744" ixy="0.0" ixz="0.0" iyy="0.045639981744" iyz="0.0" izz="0.00378" />
        </inertial>

    </link>
    <joint name="elbow_1_joint" type="revolute">
        <parent link="arm_1_link" />
        <child link="arm_2_link" />
        <origin rpy="0.0 0.0 0.0" xyz="0.5361 0.0 0.1298" />
        <axis xyz="0 0 1" />
        <limit effort="150.0" lower="-4.712388975" upper="4.712388975" velocity="3.15" />
        <dynamics damping="0.0" friction="0.0" />
    </joint>
    <link name="wrist_1_link">
        <visual>
            <geometry>
                <mesh filename="package://tm_description/meshes/tm1100/visual/Wrist1.STL" />
            </geometry>
            <material name="DarkOlive">
                <color rgba="0.3 0.3 0.25 1.0" />
            </material>
        </visual>
        <collision>
            <geometry>
                <mesh filename="package://tm_description/meshes/tm1100/collision/wrist_1.STL" />
            </geometry>
        </collision>
        
<inertial>
            <mass value="1.45" />
            <origin rpy="0 0 0" xyz="0.0 0.0 0.0" />
            <inertia ixx="0.132239947104" ixy="0.0" ixz="0.0" iyy="0.132239947104" iyz="0.0" izz="0.261" />
        </inertial>

    </link>
    <joint name="wrist_1_joint" type="revolute">
        <parent link="arm_2_link" />
        <child link="wrist_1_link" />
        <origin rpy="1.570796325 0.0 1.570796325" xyz="0.4579 0.0 -0.106" />
        <axis xyz="0 1 0" />
        <limit effort="28.0" lower="-6.2831853" upper="6.2831853" velocity="3.2" />
        <dynamics damping="0.0" friction="0.0" />
    </joint>
    <link name="wrist_2_link">
        <visual>
            <geometry>
                <mesh filename="package://tm_description/meshes/tm1100/visual/Wrist2.STL" />
            </geometry>
            <material name="DarkOlive">
                <color rgba="0.3 0.3 0.25 1.0" />
            </material>
        </visual>
        <collision>
            <geometry>
                <mesh filename="package://tm_description/meshes/tm1100/collision/wrist_2.STL" />
            </geometry>
        </collision>
        
<inertial>
            <mass value="1.45" />
            <origin rpy="0 0 0" xyz="0.0 0.0 0.0" />
            <inertia ixx="0.132239947104" ixy="0.0" ixz="0.0" iyy="0.132239947104" iyz="0.0" izz="0.261" />
        </inertial>

    </link>
    <joint name="wrist_2_joint" type="revolute">
        <parent link="wrist_1_link" />
        <child link="wrist_2_link" />
        <origin rpy="1.570796325 0.0 0.0" xyz="0.0 0.0 0.106" />
        <axis xyz="0 1 0" />
        <limit effort="28.0" lower="-6.2831853" upper="6.2831853" velocity="3.2" />
        <dynamics damping="0.0" friction="0.0" />
    </joint>
    <link name="wrist_3_link">
        <visual>
            <geometry>
                <mesh filename="package://tm_description/meshes/tm1100/visual/Wrist3.STL" />
            </geometry>
            <origin rpy="0 0 0" xyz="0 0 0.015" />
            <material name="Grey">
                <color rgba="0.5 0.5 0.5 1.0" />
            </material>
        </visual>
        <collision>
            <geometry>
                <mesh filename="package://tm_description/meshes/tm1100/collision/wrist_3.STL" />
            </geometry>
        </collision>
        
<inertial>
            <mass value="0.4" />
            <origin rpy="0 0 0" xyz="0.0 0.0 0.0" />
            <inertia ixx="0.036479985408" ixy="0.0" ixz="0.0" iyy="0.036479985408" iyz="0.0" izz="0.072" />
        </inertial>

    </link>
    <joint name="wrist_3_joint" type="revolute">
        <parent link="wrist_2_link" />
        <child link="wrist_3_link" />
        <origin rpy="0.0 0.0 0.0" xyz="0.0 0.0 0.05525" />
        <axis xyz="0 0 1" />
        <limit effort="28.0" lower="-6.2831853" upper="6.2831853" velocity="3.2" />
        <dynamics damping="0.0" friction="0.0" />
    </joint>
    <link name="tip_link">
        <collision>
            <geometry>
                <box size="0.05 0.05 0.05" />
            </geometry>
            <origin rpy="0 0 0" xyz="0 0 0.025" />
        </collision>
        
<inertial>
            <mass value="0.1" />
            <inertia ixx="0.03" iyy="0.03" izz="0.03" ixy="0.0" ixz="0.0" iyz="0.0" />
        </inertial>

    </link>
    <joint name="tip_fixed_joint" type="fixed">
        <parent link="wrist_3_link" />
        <child link="tip_link" />
        <origin rpy="0.0 0.0 0.0" xyz="0.0 0.0 0.0579" />
    </joint>
    <!-- ROS base to TM 'base_link' Coordinates transform -->
    <link name="base" />
    <joint name="base-base_link" type="fixed">
        <origin rpy="0 0 0" xyz="0 0 0" />
        <parent link="base" />
        <child link="base_link" />
    </joint>
    <!-- Frame coincident with all-zeros TCP on TM controller -->
    <link name="tool0" />
    <joint name="tip_link-tool0" type="fixed">
        <parent link="tip_link" />
        <child link="tool0" />
        <origin rpy="0 0 0" xyz="0 0 0" />
    </joint>
    <link name="world" />
    <joint name="world_joint" type="fixed">
        <parent link="world" />
        <child link="base" />
        <origin rpy="0 0 0" xyz="0 0 0" />
    </joint>
    <transmission name="trans_shoulder_1_joint">
        <type>transmission_interface/SimpleTransmission</type>
        <joint name="shoulder_1_joint">
            <hardwareInterface>hardware_interface/EffortJointInterface</hardwareInterface>
        </joint>
        <actuator name="shoulder_1_joint_motor">
            <hardwareInterface>hardware_interface/EffortJointInterface</hardwareInterface>
            <mechanicalReduction>1</mechanicalReduction>
        </actuator>
    </transmission>
    <transmission name="trans_shoulder_2_joint">
        <type>transmission_interface/SimpleTransmission</type>
        <joint name="shoulder_2_joint">
            <hardwareInterface>hardware_interface/EffortJointInterface</hardwareInterface>
        </joint>
        <actuator name="shoulder_2_joint_motor">
            <hardwareInterface>hardware_interface/EffortJointInterface</hardwareInterface>
            <mechanicalReduction>1</mechanicalReduction>
        </actuator>
    </transmission>
    <transmission name="trans_elbow_1_joint">
        <type>transmission_interface/SimpleTransmission</type>
        <joint name="elbow_1_joint">
            <hardwareInterface>hardware_interface/EffortJointInterface</hardwareInterface>
        </joint>
        <actuator name="elbow_1_joint_motor">
            <hardwareInterface>hardware_interface/EffortJointInterface</hardwareInterface>
            <mechanicalReduction>1</mechanicalReduction>
        </actuator>
    </transmission>
    <transmission name="trans_wrist_1_joint">
        <type>transmission_interface/SimpleTransmission</type>
        <joint name="wrist_1_joint">
            <hardwareInterface>hardware_interface/EffortJointInterface</hardwareInterface>
        </joint>
        <actuator name="wrist_1_joint_motor">
            <hardwareInterface>hardware_interface/EffortJointInterface</hardwareInterface>
            <mechanicalReduction>1</mechanicalReduction>
        </actuator>
    </transmission>
    <transmission name="trans_wrist_2_joint">
        <type>transmission_interface/SimpleTransmission</type>
        <joint name="wrist_2_joint">
            <hardwareInterface>hardware_interface/EffortJointInterface</hardwareInterface>
        </joint>
        <actuator name="wrist_2_joint_motor">
            <hardwareInterface>hardware_interface/EffortJointInterface</hardwareInterface>
            <mechanicalReduction>1</mechanicalReduction>
        </actuator>
    </transmission>
    <transmission name="trans_wrist_3_joint">
        <type>transmission_interface/SimpleTransmission</type>
        <joint name="wrist_3_joint">
            <hardwareInterface>hardware_interface/EffortJointInterface</hardwareInterface>
        </joint>
        <actuator name="wrist_3_joint_motor">
            <hardwareInterface>hardware_interface/EffortJointInterface</hardwareInterface>
            <mechanicalReduction>1</mechanicalReduction>
        </actuator>
    </transmission>
    <gazebo>
        <plugin name="gazebo_ros_control" filename="libgazebo_ros_control.so">
            <robotNamespace>/</robotNamespace>
        </plugin>
    </gazebo>
</robot>

<transmission name="shoulder_1_trans">
        <type>transmission_interface/SimpleTransmission</type>
        <joint name="shoulder_1_joint">
            <hardwareInterface>hardware_interface/PositionJointInterface</hardwareInterface>
        </joint>
        <actuator name="shoulder_1_motor">
            <mechanicalReduction>1</mechanicalReduction>
        </actuator>
    </transmission>
    <transmission name="shoulder_2_trans">
        <type>transmission_interface/SimpleTransmission</type>
        <joint name="shoulder_2_joint">
            <hardwareInterface>hardware_interface/PositionJointInterface</hardwareInterface>
        </joint>
        <actuator name="shoulder_2_motor">
            <mechanicalReduction>1</mechanicalReduction>
        </actuator>
    </transmission>
    <transmission name="elbow_1_trans">
        <type>transmission_interface/SimpleTransmission</type>
        <joint name="elbow_1_joint">
            <hardwareInterface>hardware_interface/PositionJointInterface</hardwareInterface>
        </joint>
        <actuator name="elbow_1_motor">
            <mechanicalReduction>1</mechanicalReduction>
        </actuator>
    </transmission>
    <transmission name="wrist_1_trans">
        <type>transmission_interface/SimpleTransmission</type>
        <joint name="wrist_1_joint">
            <hardwareInterface>hardware_interface/PositionJointInterface</hardwareInterface>
        </joint>
        <actuator name="wrist_1_motor">
            <mechanicalReduction>1</mechanicalReduction>
        </actuator>
    </transmission>
    <transmission name="wrist_2_trans">
        <type>transmission_interface/SimpleTransmission</type>
        <joint name="wrist_2_joint">
            <hardwareInterface>hardware_interface/PositionJointInterface</hardwareInterface>
        </joint>
        <actuator name="wrist_2_motor">
            <mechanicalReduction>1</mechanicalReduction>
        </actuator>
    </transmission>
    <transmission name="wrist_3_trans">
        <type>transmission_interface/SimpleTransmission</type>
        <joint name="wrist_3_joint">
            <hardwareInterface>hardware_interface/PositionJointInterface</hardwareInterface>
        </joint>
        <actuator name="wrist_3_motor">
            <mechanicalReduction>1</mechanicalReduction>
        </actuator>
    </transmission>
    <link name="base_link">
        <visual>
            <geometry>
                <mesh filename="package://tm_description/meshes/tm1100/visual/Base.STL" />
            </geometry>
            <material name="Grey">
                <color rgba="0.5 0.5 0.5 1.0" />
            </material>
        </visual>
        <collision>
            <geometry>
                <mesh filename="package://tm_description/meshes/tm1100/collision/base.STL" />
            </geometry>
        </collision>
        <inertial>
            <mass value="1.0" />
            <origin rpy="0 0 0" xyz="0.0 0.0 0.0" />
            <inertia ixx="0.00110833289" ixy="0.0" ixz="0.0" iyy="0.00110833289" iyz="0.0" izz="0.0018" />
        </inertial>
    </link>
    <link name="shoulder_1_link">
        <visual>
            <geometry>
                <mesh filename="package://tm_description/meshes/tm1100/visual/Shoulder1.STL" />
            </geometry>
            <material name="DarkOlive">
                <color rgba="0.3 0.3 0.25 1.0" />
            </material>
        </visual>
        <collision>
            <geometry>
                <mesh filename="package://tm_description/meshes/tm1100/collision/shoulder_1.STL" />
            </geometry>
        </collision>
        <inertial>
            <mass value="4.5" />
            <origin rpy="0 0 0" xyz="0.0 0.0 0.0" />
            <inertia ixx="0.012487495005" ixy="0.0" ixz="0.0" iyy="0.012487495005" iyz="0.0" izz="0.0081" />
        </inertial>
    </link>
    <joint name="shoulder_1_joint" type="revolute">
        <parent link="base_link" />
        <child link="shoulder_1_link" />
        <origin rpy="-1.570796325 0.0 0.0" xyz="0.0 0.0 0.1652" />
        <axis xyz="0 -1 0" />
        <limit effort="150.0" lower="-6.2831853" upper="6.2831853" velocity="3.15" />
        <dynamics damping="0.0" friction="0.0" />
    </joint>
    <link name="arm_1_link">
        <visual>
            <geometry>
                <mesh filename="package://tm_description/meshes/tm1100/visual/Arm1.STL" />
            </geometry>
            <material name="DarkOlive">
                <color rgba="0.3 0.3 0.25 1.0" />
            </material>
        </visual>
        <collision>
            <geometry>
                <mesh filename="package://tm_description/meshes/tm1100/collision/arm_1.STL" />
            </geometry>
        </collision>
        <inertial>
            <mass value="10.5" />
            <origin rpy="0 0 0" xyz="0.0 0.0 0.28" />
            <inertia ixx="0.28384988646" ixy="0.0" ixz="0.0" iyy="0.28384988646" iyz="0.0" izz="0.0189" />
        </inertial>
    </link>
    <joint name="shoulder_2_joint" type="revolute">
        <parent link="shoulder_1_link" />
        <child link="arm_1_link" />
        <origin rpy="0.0 0.0 -1.570796325" xyz="0.0 0.0 -0.1801" />
        <axis xyz="0 0 1" />
        <limit effort="150.0" lower="-4.712388975" upper="4.712388975" velocity="3.15" />
        <dynamics damping="0.0" friction="0.0" />
    </joint>
    <link name="arm_2_link">
        <visual>
            <geometry>
                <mesh filename="package://tm_description/meshes/tm1100/visual/Arm2.STL" />
            </geometry>
            <material name="DarkOlive">
                <color rgba="0.3 0.3 0.25 1.0" />
            </material>
        </visual>
        <collision>
            <geometry>
                <mesh filename="package://tm_description/meshes/tm1100/collision/arm_2.STL" />
            </geometry>
        </collision>
        <inertial>
            <mass value="2.1" />
            <origin rpy="0 0 0" xyz="0.0 0.0 0.25" />
            <inertia ixx="0.045639981744" ixy="0.0" ixz="0.0" iyy="0.045639981744" iyz="0.0" izz="0.00378" />
        </inertial>
    </link>
    <joint name="elbow_1_joint" type="revolute">
        <parent link="arm_1_link" />
        <child link="arm_2_link" />
        <origin rpy="0.0 0.0 0.0" xyz="0.5361 0.0 0.1298" />
        <axis xyz="0 0 1" />
        <limit effort="150.0" lower="-4.712388975" upper="4.712388975" velocity="3.15" />
        <dynamics damping="0.0" friction="0.0" />
    </joint>
    <link name="wrist_1_link">
        <visual>
            <geometry>
                <mesh filename="package://tm_description/meshes/tm1100/visual/Wrist1.STL" />
            </geometry>
            <material name="DarkOlive">
                <color rgba="0.3 0.3 0.25 1.0" />
            </material>
        </visual>
        <collision>
            <geometry>
                <mesh filename="package://tm_description/meshes/tm1100/collision/wrist_1.STL" />
            </geometry>
        </collision>
        <inertial>
            <mass value="1.45" />
            <origin rpy="0 0 0" xyz="0.0 0.0 0.0" />
            <inertia ixx="0.132239947104" ixy="0.0" ixz="0.0" iyy="0.132239947104" iyz="0.0" izz="0.261" />
        </inertial>
    </link>
    <joint name="wrist_1_joint" type="revolute">
        <parent link="arm_2_link" />
        <child link="wrist_1_link" />
        <origin rpy="1.570796325 0.0 1.570796325" xyz="0.4579 0.0 -0.106" />
        <axis xyz="0 1 0" />
        <limit effort="28.0" lower="-6.2831853" upper="6.2831853" velocity="3.2" />
        <dynamics damping="0.0" friction="0.0" />
    </joint>
    <link name="wrist_2_link">
        <visual>
            <geometry>
                <mesh filename="package://tm_description/meshes/tm1100/visual/Wrist2.STL" />
            </geometry>
            <material name="DarkOlive">
                <color rgba="0.3 0.3 0.25 1.0" />
            </material>
        </visual>
        <collision>
            <geometry>
                <mesh filename="package://tm_description/meshes/tm1100/collision/wrist_2.STL" />
            </geometry>
        </collision>
        <inertial>
            <mass value="1.45" />
            <origin rpy="0 0 0" xyz="0.0 0.0 0.0" />
            <inertia ixx="0.132239947104" ixy="0.0" ixz="0.0" iyy="0.132239947104" iyz="0.0" izz="0.261" />
        </inertial>
    </link>
    <joint name="wrist_2_joint" type="revolute">
        <parent link="wrist_1_link" />
        <child link="wrist_2_link" />
        <origin rpy="1.570796325 0.0 0.0" xyz="0.0 0.0 0.106" />
        <axis xyz="0 1 0" />
        <limit effort="28.0" lower="-6.2831853" upper="6.2831853" velocity="3.2" />
        <dynamics damping="0.0" friction="0.0" />
    </joint>
    <link name="wrist_3_link">
        <visual>
            <geometry>
                <mesh filename="package://tm_description/meshes/tm1100/visual/Wrist3.STL" />
            </geometry>
            <origin rpy="0 0 0" xyz="0 0 0.015" />
            <material name="Grey">
                <color rgba="0.5 0.5 0.5 1.0" />
            </material>
        </visual>
        <collision>
            <geometry>
                <mesh filename="package://tm_description/meshes/tm1100/collision/wrist_3.STL" />
            </geometry>
        </collision>
        <inertial>
            <mass value="0.4" />
            <origin rpy="0 0 0" xyz="0.0 0.0 0.0" />
            <inertia ixx="0.036479985408" ixy="0.0" ixz="0.0" iyy="0.036479985408" iyz="0.0" izz="0.072" />
        </inertial>
    </link>
    <joint name="wrist_3_joint" type="revolute">
        <parent link="wrist_2_link" />
        <child link="wrist_3_link" />
        <origin rpy="0.0 0.0 0.0" xyz="0.0 0.0 0.05525" />
        <axis xyz="0 0 1" />
        <limit effort="28.0" lower="-6.2831853" upper="6.2831853" velocity="3.2" />
        <dynamics damping="0.0" friction="0.0" />
    </joint>
    <link name="tip_link">
        <collision>
            <geometry>
                <box size="0.05 0.05 0.05" />
            </geometry>
            <origin rpy="0 0 0" xyz="0 0 0.025" />
        </collision>
        <inertial>
            <mass value="0.1" />
            <inertia ixx="0.03" iyy="0.03" izz="0.03" ixy="0.0" ixz="0.0" iyz="0.0" />
        </inertial>
    </link>
    <joint name="tip_fixed_joint" type="fixed">
        <parent link="wrist_3_link" />
        <child link="tip_link" />
        <origin rpy="0.0 0.0 0.0" xyz="0.0 0.0 0.0579" />
    </joint>
    <!-- ROS base to TM 'base_link' Coordinates transform -->
    <link name="base" />
    <joint name="base-base_link" type="fixed">
        <origin rpy="0 0 0" xyz="0 0 0" />
        <parent link="base" />
        <child link="base_link" />
    </joint>
    <!-- Frame coincident with all-zeros TCP on TM controller -->
    <link name="tool0" />
    <joint name="tip_link-tool0" type="fixed">
        <parent link="tip_link" />
        <child link="tool0" />
        <origin rpy="0 0 0" xyz="0 0 0" />
    </joint>
    <link name="world" />
    <joint name="world_joint" type="fixed">
        <parent link="world" />
        <child link="base" />
        <origin rpy="0 0 0" xyz="0 0 0" />
    </joint>
    <transmission name="trans_shoulder_1_joint">
        <type>transmission_interface/SimpleTransmission</type>
        <joint name="shoulder_1_joint">
            <hardwareInterface>hardware_interface/EffortJointInterface</hardwareInterface>
        </joint>
        <actuator name="shoulder_1_joint_motor">
            <hardwareInterface>hardware_interface/EffortJointInterface</hardwareInterface>
            <mechanicalReduction>1</mechanicalReduction>
        </actuator>
    </transmission>
    <transmission name="trans_shoulder_2_joint">
        <type>transmission_interface/SimpleTransmission</type>
        <joint name="shoulder_2_joint">
            <hardwareInterface>hardware_interface/EffortJointInterface</hardwareInterface>
        </joint>
        <actuator name="shoulder_2_joint_motor">
            <hardwareInterface>hardware_interface/EffortJointInterface</hardwareInterface>
            <mechanicalReduction>1</mechanicalReduction>
        </actuator>
    </transmission>
    <transmission name="trans_elbow_1_joint">
        <type>transmission_interface/SimpleTransmission</type>
        <joint name="elbow_1_joint">
            <hardwareInterface>hardware_interface/EffortJointInterface</hardwareInterface>
        </joint>
        <actuator name="elbow_1_joint_motor">
            <hardwareInterface>hardware_interface/EffortJointInterface</hardwareInterface>
            <mechanicalReduction>1</mechanicalReduction>
        </actuator>
    </transmission>
    <transmission name="trans_wrist_1_joint">
        <type>transmission_interface/SimpleTransmission</type>
        <joint name="wrist_1_joint">
            <hardwareInterface>hardware_interface/EffortJointInterface</hardwareInterface>
        </joint>
        <actuator name="wrist_1_joint_motor">
            <hardwareInterface>hardware_interface/EffortJointInterface</hardwareInterface>
            <mechanicalReduction>1</mechanicalReduction>
        </actuator>
    </transmission>
    <transmission name="trans_wrist_2_joint">
        <type>transmission_interface/SimpleTransmission</type>
        <joint name="wrist_2_joint">
            <hardwareInterface>hardware_interface/EffortJointInterface</hardwareInterface>
        </joint>
        <actuator name="wrist_2_joint_motor">
            <hardwareInterface>hardware_interface/EffortJointInterface</hardwareInterface>
            <mechanicalReduction>1</mechanicalReduction>
        </actuator>
    </transmission>
    <transmission name="trans_wrist_3_joint">
        <type>transmission_interface/SimpleTransmission</type>
        <joint name="wrist_3_joint">
            <hardwareInterface>hardware_interface/EffortJointInterface</hardwareInterface>
        </joint>
        <actuator name="wrist_3_joint_motor">
            <hardwareInterface>hardware_interface/EffortJointInterface</hardwareInterface>
            <mechanicalReduction>1</mechanicalReduction>
        </actuator>
    </transmission>
    <gazebo>
        <plugin name="gazebo_ros_control" filename="libgazebo_ros_control.so">
            <robotNamespace>/</robotNamespace>
        </plugin>
    </gazebo>
</robot>
